<?xml version='1.0'?>

<robot name="myRobot" xmlns:xacro="http://www.ros.org/wiki/xacro">
	<xacro:include filename="$(find robo)/urdf/plugin.gazebo"/>
	<xacro:property name="robot_name" value="atom" />
	<xacro:property name="chassis_mass" value="1"/>
	<xacro:property name="chassis_length" value="2"/>
	<xacro:property name="chassis_breadth" value="1"/>
	<xacro:property name="chassis_height" value="0.5"/>
	<xacro:property name="wheel_mass" value="1"/>
	<xacro:property name="wheel_width" value="0.2"/>
	<xacro:property name="wheel_radius" value="0.3"/>
	<xacro:property name="camera_mass" value="0.0001"/>

	

	
	<link name="chassis">
		<pose>0 0 0.1 0 0 0</pose>

		<inertial>
			<mass value="${chassis_mass}"/>
      		<origin xyz="0.0 0 0" rpy=" 0 0 0"/>

      		<inertia 
      			ixx="${(chassis_height*chassis_height+chassis_breadth*chassis_breadth)/12}" ixy="0" ixz="0"
      			iyy="${chassis_mass*(chassis_height*chassis_height+chassis_length*chassis_length)/12}" iyz="0"
      			izz="${chassis_mass*(chassis_length*chassis_length+chassis_breadth*chassis_breadth)/12}"
      		/>
		</inertial>

		<collision name="collision">
			<origin xyz="0 0 0.05" rpy=" 0 0 0"/>
			<geometry>
				<box size="2 1 0.5"/>
			</geometry>
		</collision>

		<visual name="chassis_visual">
			<origin xyz="0 0 0.05" rpy=" 0 0 0"/>
			<geometry>
				<box size="2 1 0.5"/>
			</geometry>

		</visual>

	</link>


	
	<link name="right_wheel_back">
		<inertial>
			<mass value="${wheel_mass}"/>
			<origin xyz="0 0 0" rpy="0 1.5707 1.5707"/>
			<inertia
				ixx="${wheel_mass*(wheel_radius*wheel_radius)/2}" ixy="0.0" ixz="0.0"
				iyy="${wheel_mass*((wheel_radius*wheel_radius)+(wheel_width*wheel_width))/12}" iyz="0.0"
				izz="${wheel_mass*((wheel_radius*wheel_radius)+(wheel_width*wheel_width))/12}"
			/>
		</inertial>

		<visual>
			<origin xyz="0 0 0" rpy="0 1.5707 1.5707"/>
			<geometry>
				<cylinder radius="${wheel_radius}" length="${wheel_width}"/>
			</geometry>
		</visual>

		<collision>
			<origin xyz="0 0 0" rpy="0 1.5707 1.5707"/>
			<geometry>
				<cylinder radius="${wheel_radius}" length="${wheel_width}"/>
			</geometry>
		</collision>

	</link>

	
	<link name="right_wheel_front">
		<inertial>
			<mass value="${wheel_mass}"/>
			<origin xyz="0 0 0" rpy="0 1.5707 1.5707"/>
			<inertia
				ixx="${wheel_mass*(wheel_radius*wheel_radius)/2}" ixy="0.0" ixz="0.0"
				iyy="${wheel_mass*((wheel_radius*wheel_radius)+(wheel_width*wheel_width))/12}" iyz="0.0"
				izz="${wheel_mass*((wheel_radius*wheel_radius)+(wheel_width*wheel_width))/12}"
			/>
		</inertial>

		<visual>
			<origin xyz="0 0 0" rpy="0 1.5707 1.5707"/>
			<geometry>
				<cylinder radius="${wheel_radius}" length="${wheel_width}"/>
			</geometry>
		</visual>

		<collision>
			<origin xyz="0 0 0" rpy="0 1.5707 1.5707"/>
			<geometry>
				<cylinder radius="${wheel_radius}" length="${wheel_width}"/>
			</geometry>
		</collision>

	</link>



	
	<link name="left_wheel_back">
		<inertial>
			<mass value="${wheel_mass}"/>
			<origin xyz="0 0 0" rpy="0 1.5707 1.5707"/>
			<inertia
				ixx="${wheel_mass*(wheel_radius*wheel_radius)/2}" ixy="0.0" ixz="0.0"
				iyy="${wheel_mass*((wheel_radius*wheel_radius)+(wheel_width*wheel_width))/12}" iyz="0.0"
				izz="${wheel_mass*((wheel_radius*wheel_radius)+(wheel_width*wheel_width))/12}"
			/>
		</inertial>

		<visual>
			<origin xyz="0 0 0" rpy="0 1.5707 1.5707"/>
			<geometry>
				<cylinder radius="${wheel_radius}" length="${wheel_width}"/>
			</geometry>
		</visual>

		<collision>
			<origin xyz="0 0 0" rpy="0 1.5707 1.5707"/>
			<geometry>
				<cylinder radius="${wheel_radius}" length="${wheel_width}"/>
			</geometry>
		</collision>

	</link>

	
	<link name="left_wheel_front">
		<inertial>
			<mass value="${wheel_mass}"/>
			<origin xyz="0 0 0" rpy="0 1.5707 1.5707"/>
			<inertia
				ixx="${wheel_mass*(wheel_radius*wheel_radius)/2}" ixy="0.0" ixz="0.0"
				iyy="${wheel_mass*((wheel_radius*wheel_radius)+(wheel_width*wheel_width))/12}" iyz="0.0"
				izz="${wheel_mass*((wheel_radius*wheel_radius)+(wheel_width*wheel_width))/12}"
			/>
		</inertial>

		<visual>
			<origin xyz="0 0 0" rpy="0 1.5707 1.5707"/>
			<geometry>
				<cylinder radius="${wheel_radius}" length="${wheel_width}"/>
			</geometry>
		</visual>

		<collision>
			<origin xyz="0 0 0" rpy="0 1.5707 1.5707"/>
			<geometry>
				<cylinder radius="${wheel_radius}" length="${wheel_width}"/>
			</geometry>
		</collision>

	</link>
	
	<link name="camera">
		<inertial>
			<mass value="${camera_mass}"/>
			<origin xyz="0 0 0" rpy="0 0 0"/>
			<inertia
				ixx="0.0001" ixy="0.0" ixz="0.0"
				iyy="0.0001" iyz="0.0"
				izz="0.0001"
			/>
		</inertial>
		
		<visual>
			<geometry>
				<box size="0.05 0.05 0.05"/>
			</geometry>
		</visual>
		
		<collision>
			<geometry>
				<box size="0.05 0.05 0.05"/>
			</geometry>
		</collision>
	</link>
	
	<link name="kinect">
		<inertial>
			<mass value="${camera_mass}"/>
			<origin xyz="0 0 0" rpy="0 0 0"/>
			<inertia
				ixx="0.0001" ixy="0.0" ixz="0.0"
				iyy="0.0001" iyz="0.0"
				izz="0.0001"
			/>
		</inertial>
		
		<visual>
			<geometry>
				<box size="0.05 0.05 0.05"/>
			</geometry>
		</visual>
		
		<collision>
			<geometry>
				<box size="0.05 0.05 0.05"/>
			</geometry>
		</collision>
	</link>
	
	<link name="gps">
		<inertial>
			<mass value="${camera_mass}"/>
			<origin xyz="0 0 0" rpy="0 0 0"/>
			<inertia
				ixx="0.0001" ixy="0.0" ixz="0.0"
				iyy="0.0001" iyz="0.0"
				izz="0.0001"
			/>
		</inertial>
		
		<visual>
			<geometry>
				<box size="0.05 0.05 0.05"/>
			</geometry>
		</visual>
		
		<collision>
			<geometry>
				<box size="0.05 0.05 0.05"/>
			</geometry>
		</collision>
	</link>
	
	<link name="laser">
		<inertial>
			<mass value="${camera_mass}"/>
			<origin xyz="0 0 0" rpy="0 0 0"/>
			<inertia
				ixx="0.0001" ixy="0.0" ixz="0.0"
				iyy="0.0001" iyz="0.0"
				izz="0.0001"
			/>
		</inertial>
		
		<visual>
			<geometry>
				<box size="0.05 0.05 0.05"/>
			</geometry>
		</visual>
		
		<collision>
			<geometry>
				<box size="0.05 0.05 0.05"/>
			</geometry>
		</collision>
	</link>
	
	<link name="sonar_link">
		<inertial>
			<mass value="${camera_mass}"/>
			<origin xyz="0 0 0" rpy="0 0 0"/>
			<inertia
				ixx="0.0001" ixy="0.0" ixz="0.0"
				iyy="0.0001" iyz="0.0"
				izz="0.0001"
			/>
		</inertial>
		
		<visual>
			<geometry>
				<box size="0.05 0.05 0.05"/>
			</geometry>
		</visual>
		
		<collision>
			<geometry>
				<box size="0.05 0.05 0.05"/>
			</geometry>
		</collision>
	</link>
	
	<link name="imu_link">
		<inertial>
			<mass value="${camera_mass}"/>
			<origin xyz="0 0 0" rpy="0 0 0"/>
			<inertia
				ixx="0.0001" ixy="0.0" ixz="0.0"
				iyy="0.0001" iyz="0.0"
				izz="0.0001"
			/>
		</inertial>
		
		<visual>
			<geometry>
				<box size="0.05 0.05 0.05"/>
			</geometry>
		</visual>
		
		<collision>
			<geometry>
				<box size="0.05 0.05 0.05"/>
			</geometry>
		</collision>
	</link>
	
	<joint type="fixed" name="imu_joint">
	    <origin xyz="0.5 0 0.325" rpy="0 0 0"/>
	    <parent link="chassis"/>
	    <child link="imu_link" />
	    <axis xyz="0 1 0" rpy="0 0 0"/>
	</joint>
	
	<joint type="fixed" name="sonar_joint">
	    <origin xyz="1.025 0 -0.1" rpy="0 0 0"/>
	    <parent link="chassis"/>
	    <child link="sonar_link" />
	    <axis xyz="0 1 0" rpy="0 0 0"/>
	</joint>
	
	<joint type="fixed" name="laser_joint">
	    <origin xyz="1.025 0 0.1" rpy="0 0 0"/>
	    <parent link="chassis"/>
	    <child link="laser" />
	    <axis xyz="0 1 0" rpy="0 0 0"/>
	</joint>



	<joint type="fixed" name="kinect_joint">
	    <origin xyz="1.025 0 0" rpy="0 0 0"/>
	    <parent link="chassis"/>
	    <child link="kinect" />
	    <axis xyz="0 1 0" rpy="0 0 0"/>
	</joint>
	
	<joint type="fixed" name="gps_joint">
	    <origin xyz="0 0 0.325" rpy="0 0 0"/>
	    <parent link="chassis"/>
	    <child link="gps" />
	    <axis xyz="0 1 0" rpy="0 0 0"/>
	</joint>
	
	<joint type="fixed" name="cam_joint">
	    <origin xyz="0.975 0 0.325" rpy="0 0 0"/>
	    <parent link="chassis"/>
	    <child link="camera" />
	    <axis xyz="0 1 0" rpy="0 0 0"/>
	</joint>

	
	<joint type="continuous" name="right_wheel_hinge_back">
	    <origin xyz="-0.7 -0.6 0" rpy="0 0 0" />
	    <parent link="chassis"/>
	    <child link="right_wheel_back" />
	    <axis xyz="0 1 0" rpy="0 0 0" />
	    <limit effort="10000" velocity="1000" />
	</joint>

	
	<joint type="continuous" name="right_wheel_hinge_front">
	    <origin xyz="0.7 -0.6 0" rpy="0 0 0" />
	    <parent link="chassis"/>
	    <child link="right_wheel_front" />
	    <axis xyz="0 1 0" rpy="0 0 0" />
	    <limit effort="10000" velocity="1000" />
	</joint>


	
	<joint type="continuous" name="left_wheel_hinge_back">
	    <origin xyz="-0.7 0.6 0" rpy="0 0 0" />
	    <parent link="chassis"/>
	    <child link="left_wheel_back" />
	    <axis xyz="0 1 0" rpy="0 0 0" />
	    <limit effort="10000" velocity="1000" />
	</joint>

	
	<joint type="continuous" name="left_wheel_hinge_front">
	    <origin xyz="0.7 0.6 0" rpy="0 0 0" />
	    <parent link="chassis"/>
	    <child link="left_wheel_front" />
	    <axis xyz="0 1 0" rpy="0 0 0" />
	    <limit effort="10000" velocity="1000" />
	</joint>

</robot>
